Workbook

Sheet Параметры
A1: academic_period_id | B1: academic_period_name | C1: days | D1: slots | E1: seed
A2: 1 | B2: 2025/2026 (2 семестр) | C2: 5 | D2: 5

Sheet Данные
A1: Группа | B1: Дисциплина | C1: Семестр | D1: Преподаватель | E1: Аудитория | F1: Приоритет | G1: Количество_пар | H1: Subject_ID | I1: Teacher_ID | J1: Audience_ID
A2: 501 | B2: Organizaciya | C2: 6 | H2: 2 | I2: ==VLOOKUP(D2, Справочник_преподавателей!A1:B5, 2, FALSE) | J2: ==VLOOKUP(E2, Справочник_аудиторий!A1:B3, 2, FALSE) -> 3
A3: 501 | B3: EOSI | C3: 6 | H3: 1 | I3: ==VLOOKUP(D3, Справочник_преподавателей!A1:B5, 2, FALSE) | J3: ==VLOOKUP(E3, Справочник_аудиторий!A1:B3, 2, FALSE) -> 2
A4: СА-502 | B4: Алгоритмизация | C4: 4 | H4: 4 | I4: ==VLOOKUP(D4, Справочник_преподавателей!A1:B5, 2, FALSE) | J4: ==VLOOKUP(E4, Справочник_аудиторий!A1:B3, 2, FALSE) -> 3
A5: СА-502 | B5: Операционные системы и среды | C5: 4 | H5: 3 | I5: ==VLOOKUP(D5, Справочник_преподавателей!A1:B5, 2, FALSE) | J5: ==VLOOKUP(E5, Справочник_аудиторий!A1:B3, 2, FALSE) -> 4
A6: СА-503 | B6: Литература | C6: 1 | H6: 12 | I6: ==VLOOKUP(D6, Справочник_преподавателей!A1:B5, 2, FALSE) | J6: ==VLOOKUP(E6, Справочник_аудиторий!A1:B3, 2, FALSE) -> 4
A7: СА-503 | B7: Информатика | C7: 1 | H7: 11 | I7: ==VLOOKUP(D7, Справочник_преподавателей!A1:B5, 2, FALSE) | J7: ==VLOOKUP(E7, Справочник_аудиторий!A1:B3, 2, FALSE) -> 2
A8: СА-503 | B8: Русский язык | C8: 1 | H8: 10 | I8: ==VLOOKUP(D8, Справочник_преподавателей!A1:B5, 2, FALSE) | J8: ==VLOOKUP(E8, Справочник_аудиторий!A1:B3, 2, FALSE) -> 4
A9: СА-503 | B9: Математика | C9: 1 | H9: 9 | I9: ==VLOOKUP(D9, Справочник_преподавателей!A1:B5, 2, FALSE) | J9: ==VLOOKUP(E9, Справочник_аудиторий!A1:B3, 2, FALSE) -> 3
I10: ==VLOOKUP(D10, Справочник_преподавателей!A1:B5, 2, FALSE) | J10: ==VLOOKUP(E10, Справочник_аудиторий!A1:B3, 2, FALSE)
I11: ==VLOOKUP(D11, Справочник_преподавателей!A1:B5, 2, FALSE) | J11: ==VLOOKUP(E11, Справочник_аудиторий!A1:B3, 2, FALSE)
I12: ==VLOOKUP(D12, Справочник_преподавателей!A1:B5, 2, FALSE) | J12: ==VLOOKUP(E12, Справочник_аудиторий!A1:B3, 2, FALSE)
I13: ==VLOOKUP(D13, Справочник_преподавателей!A1:B5, 2, FALSE) | J13: ==VLOOKUP(E13, Справочник_аудиторий!A1:B3, 2, FALSE)
I14: ==VLOOKUP(D14, Справочник_преподавателей!A1:B5, 2, FALSE) | J14: ==VLOOKUP(E14, Справочник_аудиторий!A1:B3, 2, FALSE)
I15: ==VLOOKUP(D15, Справочник_преподавателей!A1:B5, 2, FALSE) | J15: ==VLOOKUP(E15, Справочник_аудиторий!A1:B3, 2, FALSE)
I16: ==VLOOKUP(D16, Справочник_преподавателей!A1:B5, 2, FALSE) | J16: ==VLOOKUP(E16, Справочник_аудиторий!A1:B3, 2, FALSE)
I17: ==VLOOKUP(D17, Справочник_преподавателей!A1:B5, 2, FALSE) | J17: ==VLOOKUP(E17, Справочник_аудиторий!A1:B3, 2, FALSE)
I18: ==VLOOKUP(D18, Справочник_преподавателей!A1:B5, 2, FALSE) | J18: ==VLOOKUP(E18, Справочник_аудиторий!A1:B3, 2, FALSE)
I19: ==VLOOKUP(D19, Справочник_преподавателей!A1:B5, 2, FALSE) | J19: ==VLOOKUP(E19, Справочник_аудиторий!A1:B3, 2, FALSE)
I20: ==VLOOKUP(D20, Справочник_преподавателей!A1:B5, 2, FALSE) | J20: ==VLOOKUP(E20, Справочник_аудиторий!A1:B3, 2, FALSE)
I21: ==VLOOKUP(D21, Справочник_преподавателей!A1:B5, 2, FALSE) | J21: ==VLOOKUP(E21, Справочник_аудиторий!A1:B3, 2, FALSE)
I22: ==VLOOKUP(D22, Справочник_преподавателей!A1:B5, 2, FALSE) | J22: ==VLOOKUP(E22, Справочник_аудиторий!A1:B3, 2, FALSE)
I23: ==VLOOKUP(D23, Справочник_преподавателей!A1:B5, 2, FALSE) | J23: ==VLOOKUP(E23, Справочник_аудиторий!A1:B3, 2, FALSE)
I24: ==VLOOKUP(D24, Справочник_преподавателей!A1:B5, 2, FALSE) | J24: ==VLOOKUP(E24, Справочник_аудиторий!A1:B3, 2, FALSE)
I25: ==VLOOKUP(D25, Справочник_преподавателей!A1:B5, 2, FALSE) | J25: ==VLOOKUP(E25, Справочник_аудиторий!A1:B3, 2, FALSE)
I26: ==VLOOKUP(D26, Справочник_преподавателей!A1:B5, 2, FALSE) | J26: ==VLOOKUP(E26, Справочник_аудиторий!A1:B3, 2, FALSE)
I27: ==VLOOKUP(D27, Справочник_преподавателей!A1:B5, 2, FALSE) | J27: ==VLOOKUP(E27, Справочник_аудиторий!A1:B3, 2, FALSE)
I28: ==VLOOKUP(D28, Справочник_преподавателей!A1:B5, 2, FALSE) | J28: ==VLOOKUP(E28, Справочник_аудиторий!A1:B3, 2, FALSE)
I29: ==VLOOKUP(D29, Справочник_преподавателей!A1:B5, 2, FALSE) | J29: ==VLOOKUP(E29, Справочник_аудиторий!A1:B3, 2, FALSE)
I30: ==VLOOKUP(D30, Справочник_преподавателей!A1:B5, 2, FALSE) | J30: ==VLOOKUP(E30, Справочник_аудиторий!A1:B3, 2, FALSE)
I31: ==VLOOKUP(D31, Справочник_преподавателей!A1:B5, 2, FALSE) | J31: ==VLOOKUP(E31, Справочник_аудиторий!A1:B3, 2, FALSE)
I32: ==VLOOKUP(D32, Справочник_преподавателей!A1:B5, 2, FALSE) | J32: ==VLOOKUP(E32, Справочник_аудиторий!A1:B3, 2, FALSE)
I33: ==VLOOKUP(D33, Справочник_преподавателей!A1:B5, 2, FALSE) | J33: ==VLOOKUP(E33, Справочник_аудиторий!A1:B3, 2, FALSE)
I34: ==VLOOKUP(D34, Справочник_преподавателей!A1:B5, 2, FALSE) | J34: ==VLOOKUP(E34, Справочник_аудиторий!A1:B3, 2, FALSE)
I35: ==VLOOKUP(D35, Справочник_преподавателей!A1:B5, 2, FALSE) | J35: ==VLOOKUP(E35, Справочник_аудиторий!A1:B3, 2, FALSE)
I36: ==VLOOKUP(D36, Справочник_преподавателей!A1:B5, 2, FALSE) | J36: ==VLOOKUP(E36, Справочник_аудиторий!A1:B3, 2, FALSE)
I37: ==VLOOKUP(D37, Справочник_преподавателей!A1:B5, 2, FALSE) | J37: ==VLOOKUP(E37, Справочник_аудиторий!A1:B3, 2, FALSE)
I38: ==VLOOKUP(D38, Справочник_преподавателей!A1:B5, 2, FALSE) | J38: ==VLOOKUP(E38, Справочник_аудиторий!A1:B3, 2, FALSE)
I39: ==VLOOKUP(D39, Справочник_преподавателей!A1:B5, 2, FALSE) | J39: ==VLOOKUP(E39, Справочник_аудиторий!A1:B3, 2, FALSE)
I40: ==VLOOKUP(D40, Справочник_преподавателей!A1:B5, 2, FALSE) | J40: ==VLOOKUP(E40, Справочник_аудиторий!A1:B3, 2, FALSE)
...

Sheet Справочник_преподавателей
A1: Teacher | B1: 2
A2: Teacher2 | B2: 3
A3: Лятти Алексей Александрович | B3: 6
A4: Петров Петр Петрович | B4: 9
A5: Преподов Препод Преподович | B5: 10

Sheet Справочник_аудиторий
A1: 409 | B1: 1
A2: 101 | B2: 2
A3: 308 | B3: 3
