Workbook

Sheet Параметры
A1: academic_period_id | B1: academic_period_name | C1: days | D1: slots | E1: seed
A2: 1 | B2: 2025/2026 (2 семестр) | C2: 6 | D2: 6

Sheet Данные
A1: Группа | B1: Дисциплина | C1: Семестр | D1: Преподаватель | E1: Аудитория | F1: Приоритет | G1: Количество_пар | H1: Subject_ID | I1: Teacher_ID | J1: Audience_ID
A2: СА-503 | B2: Математика | C2: 2 | D2: Лятти Алексей Александрович | E2: 409 | G2: 5 | H2: 40 | I2: =VLOOKUP(D2, Справочник_преподавателей!A1:B6, 2, FALSE()) -> 6 | J2: =VLOOKUP(E2, Справочник_аудиторий!A1:B5, 2, FALSE()) -> 1
A3: СА-503 | B3: Электротехника | C3: 2 | D3: Козлов Дмитрий Андреевич | E3: 101 | G3: 6 | H3: 43 | I3: =VLOOKUP(D3, Справочник_преподавателей!A1:B6, 2, FALSE()) -> 17 | J3: =VLOOKUP(E3, Справочник_аудиторий!A1:B5, 2, FALSE()) -> 2
A4: СА-503 | B4: Английский язык | C4: 2 | D4: Иванов Иван Иванович | E4: 102 | G4: 4 | H4: 42 | I4: =VLOOKUP(D4, Справочник_преподавателей!A1:B6, 2, FALSE()) -> 14 | J4: =VLOOKUP(E4, Справочник_аудиторий!A1:B5, 2, FALSE()) -> 3
A5: СА-503 | B5: Информатика | C5: 2 | D5: Сидоров Алексей Викторович | E5: 103 | G5: 6 | H5: 41 | I5: =VLOOKUP(D5, Справочник_преподавателей!A1:B6, 2, FALSE()) -> 16 | J5: =VLOOKUP(E5, Справочник_аудиторий!A1:B5, 2, FALSE()) -> 4
A6: Ш-208 | B6: Электротехника | C6: 2 | D6: Козлов Дмитрий Андреевич | E6: 101 | G6: 6 | H6: 39 | I6: =VLOOKUP(D6, Справочник_преподавателей!A1:B6, 2, FALSE()) -> 17 | J6: =VLOOKUP(E6, Справочник_аудиторий!A1:B5, 2, FALSE()) -> 2
A7: Ш-208 | B7: Английский язык | C7: 2 | D7: Иванов Иван Иванович | E7: 104 | G7: 4 | H7: 38 | I7: =VLOOKUP(D7, Справочник_преподавателей!A1:B6, 2, FALSE()) -> 14 | J7: =VLOOKUP(E7, Справочник_аудиторий!A1:B5, 2, FALSE()) -> 5
A8: Ш-208 | B8: Информатика | C8: 2 | D8: Сидоров Алексей Викторович | E8: 102 | G8: 6 | H8: 37 | I8: =VLOOKUP(D8, Справочник_преподавателей!A1:B6, 2, FALSE()) -> 16 | J8: =VLOOKUP(E8, Справочник_аудиторий!A1:B5, 2, FALSE()) -> 3
A9: Ш-208 | B9: Математика | C9: 2 | D9: Лятти Алексей Александрович | E9: 409 | G9: 5 | H9: 36 | I9: =VLOOKUP(D9, Справочник_преподавателей!A1:B6, 2, FALSE()) -> 6 | J9: =VLOOKUP(E9, Справочник_аудиторий!A1:B5, 2, FALSE()) -> 1
I10: =VLOOKUP(D10, Справочник_преподавателей!A1:B6, 2, FALSE()) -> #N/A | J10: =VLOOKUP(E10, Справочник_аудиторий!A1:B5, 2, FALSE()) -> #N/A
I11: =VLOOKUP(D11, Справочник_преподавателей!A1:B6, 2, FALSE()) -> #N/A | J11: =VLOOKUP(E11, Справочник_аудиторий!A1:B5, 2, FALSE()) -> #N/A
I12: =VLOOKUP(D12, Справочник_преподавателей!A1:B6, 2, FALSE()) -> #N/A | J12: =VLOOKUP(E12, Справочник_аудиторий!A1:B5, 2, FALSE()) -> #N/A
I13: =VLOOKUP(D13, Справочник_преподавателей!A1:B6, 2, FALSE()) -> #N/A | J13: =VLOOKUP(E13, Справочник_аудиторий!A1:B5, 2, FALSE()) -> #N/A
I14: =VLOOKUP(D14, Справочник_преподавателей!A1:B6, 2, FALSE()) -> #N/A | J14: =VLOOKUP(E14, Справочник_аудиторий!A1:B5, 2, FALSE()) -> #N/A
I15: =VLOOKUP(D15, Справочник_преподавателей!A1:B6, 2, FALSE()) -> #N/A | J15: =VLOOKUP(E15, Справочник_аудиторий!A1:B5, 2, FALSE()) -> #N/A
I16: =VLOOKUP(D16, Справочник_преподавателей!A1:B6, 2, FALSE()) -> #N/A | J16: =VLOOKUP(E16, Справочник_аудиторий!A1:B5, 2, FALSE()) -> #N/A
I17: =VLOOKUP(D17, Справочник_преподавателей!A1:B6, 2, FALSE()) -> #N/A | J17: =VLOOKUP(E17, Справочник_аудиторий!A1:B5, 2, FALSE()) -> #N/A
I18: =VLOOKUP(D18, Справочник_преподавателей!A1:B6, 2, FALSE()) -> #N/A | J18: =VLOOKUP(E18, Справочник_аудиторий!A1:B5, 2, FALSE()) -> #N/A
I19: =VLOOKUP(D19, Справочник_преподавателей!A1:B6, 2, FALSE()) -> #N/A | J19: =VLOOKUP(E19, Справочник_аудиторий!A1:B5, 2, FALSE()) -> #N/A
I20: =VLOOKUP(D20, Справочник_преподавателей!A1:B6, 2, FALSE()) -> #N/A | J20: =VLOOKUP(E20, Справочник_аудиторий!A1:B5, 2, FALSE()) -> #N/A
I21: =VLOOKUP(D21, Справочник_преподавателей!A1:B6, 2, FALSE()) -> #N/A | J21: =VLOOKUP(E21, Справочник_аудиторий!A1:B5, 2, FALSE()) -> #N/A
I22: =VLOOKUP(D22, Справочник_преподавателей!A1:B6, 2, FALSE()) -> #N/A | J22: =VLOOKUP(E22, Справочник_аудиторий!A1:B5, 2, FALSE()) -> #N/A
I23: =VLOOKUP(D23, Справочник_преподавателей!A1:B6, 2, FALSE()) -> #N/A | J23: =VLOOKUP(E23, Справочник_аудиторий!A1:B5, 2, FALSE()) -> #N/A
I24: =VLOOKUP(D24, Справочник_преподавателей!A1:B6, 2, FALSE()) -> #N/A | J24: =VLOOKUP(E24, Справочник_аудиторий!A1:B5, 2, FALSE()) -> #N/A
I25: =VLOOKUP(D25, Справочник_преподавателей!A1:B6, 2, FALSE()) -> #N/A | J25: =VLOOKUP(E25, Справочник_аудиторий!A1:B5, 2, FALSE()) -> #N/A
I26: =VLOOKUP(D26, Справочник_преподавателей!A1:B6, 2, FALSE()) -> #N/A | J26: =VLOOKUP(E26, Справочник_аудиторий!A1:B5, 2, FALSE()) -> #N/A
I27: =VLOOKUP(D27, Справочник_преподавателей!A1:B6, 2, FALSE()) -> #N/A | J27: =VLOOKUP(E27, Справочник_аудиторий!A1:B5, 2, FALSE()) -> #N/A
I28: =VLOOKUP(D28, Справочник_преподавателей!A1:B6, 2, FALSE()) -> #N/A | J28: =VLOOKUP(E28, Справочник_аудиторий!A1:B5, 2, FALSE()) -> #N/A
I29: =VLOOKUP(D29, Справочник_преподавателей!A1:B6, 2, FALSE()) -> #N/A | J29: =VLOOKUP(E29, Справочник_аудиторий!A1:B5, 2, FALSE()) -> #N/A
I30: =VLOOKUP(D30, Справочник_преподавателей!A1:B6, 2, FALSE()) -> #N/A | J30: =VLOOKUP(E30, Справочник_аудиторий!A1:B5, 2, FALSE()) -> #N/A
I31: =VLOOKUP(D31, Справочник_преподавателей!A1:B6, 2, FALSE()) -> #N/A | J31: =VLOOKUP(E31, Справочник_аудиторий!A1:B5, 2, FALSE()) -> #N/A
I32: =VLOOKUP(D32, Справочник_преподавателей!A1:B6, 2, FALSE()) -> #N/A | J32: =VLOOKUP(E32, Справочник_аудиторий!A1:B5, 2, FALSE()) -> #N/A
I33: =VLOOKUP(D33, Справочник_преподавателей!A1:B6, 2, FALSE()) -> #N/A | J33: =VLOOKUP(E33, Справочник_аудиторий!A1:B5, 2, FALSE()) -> #N/A
I34: =VLOOKUP(D34, Справочник_преподавателей!A1:B6, 2, FALSE()) -> #N/A | J34: =VLOOKUP(E34, Справочник_аудиторий!A1:B5, 2, FALSE()) -> #N/A
I35: =VLOOKUP(D35, Справочник_преподавателей!A1:B6, 2, FALSE()) -> #N/A | J35: =VLOOKUP(E35, Справочник_аудиторий!A1:B5, 2, FALSE()) -> #N/A
I36: =VLOOKUP(D36, Справочник_преподавателей!A1:B6, 2, FALSE()) -> #N/A | J36: =VLOOKUP(E36, Справочник_аудиторий!A1:B5, 2, FALSE()) -> #N/A
I37: =VLOOKUP(D37, Справочник_преподавателей!A1:B6, 2, FALSE()) -> #N/A | J37: =VLOOKUP(E37, Справочник_аудиторий!A1:B5, 2, FALSE()) -> #N/A
I38: =VLOOKUP(D38, Справочник_преподавателей!A1:B6, 2, FALSE()) -> #N/A | J38: =VLOOKUP(E38, Справочник_аудиторий!A1:B5, 2, FALSE()) -> #N/A
I39: =VLOOKUP(D39, Справочник_преподавателей!A1:B6, 2, FALSE()) -> #N/A | J39: =VLOOKUP(E39, Справочник_аудиторий!A1:B5, 2, FALSE()) -> #N/A
I40: =VLOOKUP(D40, Справочник_преподавателей!A1:B6, 2, FALSE()) -> #N/A | J40: =VLOOKUP(E40, Справочник_аудиторий!A1:B5, 2, FALSE()) -> #N/A
...

Sheet Справочник_преподавателей
A1: Teacher | B1: 2
A2: Лятти Алексей Александрович | B2: 6
A3: Иванов Иван Иванович | B3: 14
A4: Петрова Мария Сергеевна | B4: 15
A5: Сидоров Алексей Викторович | B5: 16
A6: Козлов Дмитрий Андреевич | B6: 17

Sheet Справочник_аудиторий
A1: 409 | B1: 1
A2: 101 | B2: 2
A3: 102 | B3: 3
A4: 103 | B4: 4
A5: 104 | B5: 5
